Workbook

Sheet Summary
A1: HHCS CareDesk: catalogue, pricing and training readiness
A3: Status | B3: Not ready. No approved final price list was available and the live database could not be read, so no price was imported, approved or activated.
A4: What this reconciles | B4: The CRM rate card as the repo migrations define it, against the only catalogue file in the repo: a planning draft ("85 Services Catalogue", 95 rows). The draft is not an approved list.
A5: Headline counts | B5: See Totals. All counts are formulas over the Reconciliation sheet.
A6: Cost confidentiality | B6: Verified by tests and code reading: see Verification evidence. Two paths (BMM API, partner sheet) were checked by reading only.
A7: Next step | B7: Send the approved price list file (or confirm the draft line by line on "Draft values to confirm"), plus the GST basis, effective date and unit decisions. Then run Import rates > Check file and share the check report before Submit.
A8: Sheets | B8: Totals, Reconciliation, Unresolved inputs, Unit decisions, Draft values to confirm, Knowledge coverage, Scripts review, Proposed S-08, Awaiting approval, Verification evidence, Assumptions.
A9: Yellow cells | B9: For the business owner to fill. Everything else is computed or sourced.

Sheet Totals
A1: Totals
A2: Every count is a formula over the Reconciliation sheet. "Approved list" cannot be counted: no approved list was available.
A4: Measure | B4: Against the approved list | C4: CRM rate card (repo migrations) | D4: Unapproved draft (reference only) | E4: How it is counted
A5: Expected services | B5: Not determinable | C5: =COUNTIF(Reconciliation!$Y$6:$Y$110,"Y") -> 40 | D5: =COUNTIF(Reconciliation!$Z$6:$Z$110,"Y") -> 95 | E5: Rows present in each source. The 80 to 90 figure is an expectation only; the draft has 95 rows despite its "85" title.
A6: Matched (same code in CRM and draft) | B6: Not determinable | C6: =COUNTIFS(Reconciliation!$Y$6:$Y$110,"Y",Reconciliation!$Z$6:$Z$110,"Y") -> 30 | D6: =COUNTIFS(Reconciliation!$Y$6:$Y$110,"Y",Reconciliation!$Z$6:$Z$110,"Y") -> 30 | E6: Exact code only. Similar names are never matched (importer rule).
A7: Missing from the CRM | B7: Not determinable | D7: =COUNTIFS(Reconciliation!$Z$6:$Z$110,"Y",Reconciliation!$Y$6:$Y$110,"N") -> 65 | E7: In the draft, not on the rate card.
A8: On the CRM but not in the draft | B8: Not determinable | C8: =COUNTIFS(Reconciliation!$Y$6:$Y$110,"Y",Reconciliation!$Z$6:$Z$110,"N") -> 10 | E8: Mostly generic BMM codes and the three home X-ray items.
A9: Duplicate codes | B9: Not determinable | C9: =SUMPRODUCT((COUNTIF(Reconciliation!$A$6:$A$110,Reconciliation!$A$6:$A$110)>1)*(Reconciliation!$Y$6:$Y$110="Y")) -> 0 | D9: 0 | E9: Codes appearing more than once. The draft was checked separately in Python: 95 rows, 95 unique codes, no duplicate names.
A10: Possible overlaps (generic vs specific) | B10: Not determinable | C10: =COUNTIFS(Reconciliation!$AG$6:$AG$110,1,Reconciliation!$Y$6:$Y$110,"Y") -> 12 | D10: =COUNTIFS(Reconciliation!$AG$6:$AG$110,1,Reconciliation!$Z$6:$Z$110,"Y") -> 21 | E10: E.g. BED-HOSP vs BED-SEMI / BED-FOWL; XR-HOME vs XR-CHEST. A business decision, not merged automatically.
A11: Inactive | B11: Not determinable | C11: =COUNTIFS(Reconciliation!$W$6:$W$110,"Inactive",Reconciliation!$Y$6:$Y$110,"Y") -> 0 | E11: services.active = false.
A12: Awaiting approval | B12: Not determinable | C12: 0 in repo; live unknown | E12: No rate_imports and no pending approvals exist in the migration end state. Live Approvals page not readable from here.
A13: Active but not priced (Rs 0) | B13: Not determinable | C13: =COUNTIF(Reconciliation!$AH$6:$AH$110,1) -> 25 | E13: Seeded with price 0 and an automatic approved_at; not quotable.
A14: Missing buying cost | B14: Not determinable | C14: =COUNTIF(Reconciliation!$AE$6:$AE$110,1) -> 40 | E14: provider_rates has 0 rows in the migration end state.
A15: Buying cost derivable by the 70% rule now | B15: Not determinable | C15: =COUNT(Reconciliation!$P$6:$P$110) -> 15 | E15: CRM rows with a selling price above 0.
A16: Draft B2B not equal to 70% of draft B2C | B16: Not determinable | D16: =COUNTIF(Reconciliation!$Q$6:$Q$110,"Differs*") -> 94 | E16: Would be provider-specific exceptions. None is documented as approved.
A17: Unit mismatch or unit needing a decision | B17: Not determinable | C17: =COUNTIFS(Reconciliation!$AC$6:$AC$110,1,Reconciliation!$Y$6:$Y$110,"Y") -> 16 | D17: =COUNTIFS(Reconciliation!$AC$6:$AC$110,1,Reconciliation!$Z$6:$Z$110,"Y") -> 31 | E17: Different wording between sources, 24 h labelled "shift", pack size differences, free-text units.
A18: GST basis not confirmed | B18: Not determinable | C18: =COUNTIFS(Reconciliation!$AD$6:$AD$110,1,Reconciliation!$Y$6:$Y$110,"Y") -> 40 | D18: =COUNTIFS(Reconciliation!$AD$6:$AD$110,1,Reconciliation!$Z$6:$Z$110,"Y") -> 95 | E18: No row in either source states incl_gst / excl_gst / no_gst.
A19: Tax mismatch (two confirmed bases disagree) | B19: Not determinable | C19: 0 | D19: 0 | E19: Cannot occur yet: no basis is confirmed anywhere.
A20: Effective date missing | B20: Not determinable | C20: =COUNTIFS(Reconciliation!$V$6:$V$110,"Not given",Reconciliation!$Y$6:$Y$110,"Y") -> 40 | D20: =COUNTIFS(Reconciliation!$V$6:$V$110,"Not given",Reconciliation!$Z$6:$Z$110,"Y") -> 95 | E20: Neither source carries an effective date.
A21: Knowledge gaps (no service-specific notes) | B21: Not determinable | C21: =COUNTIFS(Reconciliation!$AF$6:$AF$110,1,Reconciliation!$Y$6:$Y$110,"Y") -> 40 | D21: =COUNTIFS(Reconciliation!$AF$6:$AF$110,1,Reconciliation!$Z$6:$Z$110,"Y") -> 95 | E21: service_knowledge holds 12 category defaults and 0 service rows.
A22: Name or meaning differs on a matched code | B22: Not determinable | C22: =COUNTIF(Reconciliation!$AI$6:$AI$110,1) -> 1 | E22: VISIT-STD: "Home visit charge" vs "Home Assessment & Care Coordinator Visit".

Sheet Assumptions
A1: Assumptions
A3: Item | B3: Value | C3: Source
A4: B2B as a share of B2C (HHCS rule) | B4: 0.7 | C4: docs/RATES-AND-MARGINS.md, "B2B = % of B2C": HHCS rule (Oct 2026) 70; commit 3af8698. Used only for the derivation column; the importer computes the real value on the server.
A5: Provider by category | B5: SM / BMM | C5: docs/RATES-AND-MARGINS.md: lab, X-ray, ECG and visit to SecondMedic; everything else (incl. "other") to Book My Medicare.
A6: Unit comparison | B6: normalised | C6: Trimmed, lower-cased, leading "per" dropped. Never converted (docs/RATES-AND-MARGINS.md, Terms > Unit).

Sheet Reconciliation
A1: Service reconciliation: CRM rate card vs the only catalogue file found (unapproved draft)
A2: No approved final price list was available, and the live database could not be read. "Approved B2C" is therefore blank on every row. CRM values are the end state of all repo migrations applied to a throwaway database; the live database may differ if imports or approvals were done in the app.
A5: Code | B5: CRM name | C5: Draft name | D5: Category | E5: Delivery provider (routing) | F5: Draft provider | G5: CRM unit | H5: Draft unit | I5: Unit note | J5: CRM B2C (Rs) | K5: Draft B2C (Rs, unapproved) | L5: Approved B2C (Rs) | M5: B2C status | N5: CRM B2B | O5: Draft B2B (Rs, unapproved) | P5: 70% of CRM B2C (Rs, derivation) | Q5: Draft B2B vs 70% of draft B2C | R5: B2B status | S5: CRM GST basis | T5: Draft GST | U5: Tax status | V5: Effective date | W5: Approval / activation | X5: Knowledge coverage | Y5: On CRM rate card | Z5: In draft | AA5: Possible overlap with | AB5: Issues | AC5: Flag: unit | AD5: Flag: GST basis | AE5: Flag: no B2B | AF5: Flag: knowledge | AG5: Flag: overlap | AH5: Flag: unpriced | AI5: Flag: meaning differs
A6: BED-FOWL | C6: Full Fowler 2-Function Hospital Bed (Rental) | D6: beds | E6: Book My Medicare (BMM) | F6: Book My Medicare (BMM) | H6: day | I6: Daily rental. No monthly rental rate exists in any source; a month is not 30 day rates. | K6: 240 | M6: Not on the CRM rate card | N6: Not loaded | O6: 160 | P6: =IF(AND(ISNUMBER(J6),J6>0),ROUND(J6*Assumptions!$B$4,2),"") | Q6: =IF(AND(ISNUMBER(K6),ISNUMBER(O6)),IF(ROUND(K6*Assumptions!$B$4,2)=O6,"Equals 70%","Differs ("&TEXT(O6/K6,"0%")&" of B2C)"),"") -> Differs (67% of B2C) | R6: Not loaded. Draft B2B is unapproved. | T6: 18% GST | U6: Not confirmed: CRM basis is empty; draft gives a GST rate, not whether prices include it | V6: Not given | W6: Not loaded | X6: No service yet. Category notes (beds) would apply after import. | Y6: N | Z6: Y | AA6: BED-HOSP | AB6: GST basis, Knowledge, Possible overlap | AC6: 0 | AD6: 1 | AE6: 0 | AF6: 1 | AG6: 1 | AH6: 0 | AI6: 0
A7: BED-HOSP | B7: Hospital bed on rent | D7: beds | E7: Book My Medicare (BMM) | G7: day | I7: Daily rental. No monthly rental rate exists in any source; a month is not 30 day rates. | J7: 0 | M7: Not priced: Rs 0 placeholder, agents see "quote required" | N7: None (0 buying rates in CRM) | P7: =IF(AND(ISNUMBER(J7),J7>0),ROUND(J7*Assumptions!$B$4,2),"") | Q7: =IF(AND(ISNUMBER(K7),ISNUMBER(O7)),IF(ROUND(K7*Assumptions!$B$4,2)=O7,"Equals 70%","Differs ("&TEXT(O7/K7,"0%")&" of B2C)"),"") | R7: No buying rate, and none derivable: no selling price. | S7: Not set | U7: Not confirmed: CRM basis is empty | V7: Not given | W7: Active, not quotable (Rs 0) | X7: Category notes only (beds). No service-specific notes. | Y7: Y | Z7: N | AA7: BED-SEMI, BED-FOWL | AB7: Unpriced, No B2B, GST basis, Knowledge, Possible overlap | AC7: 0 | AD7: 1 | AE7: 1 | AF7: 1 | AG7: 1 | AH7: 1 | AI7: 0
A8: BED-ICU | B8: ICU bed (motorised), rental | C8: Motorized ICU Bed (3/5 Function with Remote) | D8: beds | E8: Book My Medicare (BMM) | F8: Book My Medicare (BMM) | G8: day | H8: day | I8: Daily rental. No monthly rental rate exists in any source; a month is not 30 day rates. | J8: 0 | K8: 450 | M8: Not priced: Rs 0 placeholder, agents see "quote required" | N8: None (0 buying rates in CRM) | O8: 300 | P8: =IF(AND(ISNUMBER(J8),J8>0),ROUND(J8*Assumptions!$B$4,2),"") | Q8: =IF(AND(ISNUMBER(K8),ISNUMBER(O8)),IF(ROUND(K8*Assumptions!$B$4,2)=O8,"Equals 70%","Differs ("&TEXT(O8/K8,"0%")&" of B2C)"),"") -> Differs (67% of B2C) | R8: No buying rate, and none derivable: no selling price. Draft B2B is unapproved. | S8: Not set | T8: 18% GST | U8: Not confirmed: CRM basis is empty; draft gives a GST rate, not whether prices include it | V8: Not given | W8: Active, not quotable (Rs 0) | X8: Category notes only (beds). No service-specific notes. | Y8: Y | Z8: Y | AB8: Unpriced, No B2B, GST basis, Knowledge | AC8: 0 | AD8: 1 | AE8: 1 | AF8: 1 | AG8: 0 | AH8: 1 | AI8: 0
A9: BED-SEMI | C9: Semi-Fowler Hospital Bed with Railings (Rental) | D9: beds | E9: Book My Medicare (BMM) | F9: Book My Medicare (BMM) | H9: day | I9: Daily rental. No monthly rental rate exists in any source; a month is not 30 day rates. | K9: 180 | M9: Not on the CRM rate card | N9: Not loaded | O9: 120 | P9: =IF(AND(ISNUMBER(J9),J9>0),ROUND(J9*Assumptions!$B$4,2),"") | Q9: =IF(AND(ISNUMBER(K9),ISNUMBER(O9)),IF(ROUND(K9*Assumptions!$B$4,2)=O9,"Equals 70%","Differs ("&TEXT(O9/K9,"0%")&" of B2C)"),"") -> Differs (67% of B2C) | R9: Not loaded. Draft B2B is unapproved. | T9: 18% GST | U9: Not confirmed: CRM basis is empty; draft gives a GST rate, not whether prices include it | V9: Not given | W9: Not loaded | X9: No service yet. Category notes (beds) would apply after import. | Y9: N | Z9: Y | AA9: BED-HOSP | AB9: GST basis, Knowledge, Possible overlap | AC9: 0 | AD9: 1 | AE9: 0 | AF9: 1 | AG9: 1 | AH9: 0 | AI9: 0
A10: TYNA-BED | B10: Tyna Bed / Positioning Alternating Mattress | C10: Tubular High-Risk Pressure Redistribution Bed | D10: beds | E10: Book My Medicare (BMM) | F10: Book My Medicare (BMM) | G10: day | H10: day | I10: Daily rental. No monthly rental rate exists in any source; a month is not 30 day rates. | J10: 0 | K10: 150 | M10: Not priced: Rs 0 placeholder, agents see "quote required" | N10: None (0 buying rates in CRM) | O10: 100 | P10: =IF(AND(ISNUMBER(J10),J10>0),ROUND(J10*Assumptions!$B$4,2),"") | Q10: =IF(AND(ISNUMBER(K10),ISNUMBER(O10)),IF(ROUND(K10*Assumptions!$B$4,2)=O10,"Equals 70%","Differs ("&TEXT(O10/K10,"0%")&" of B2C)"),"") -> Differs (67% of B2C) | R10: No buying rate, and none derivable: no selling price. Draft B2B is unapproved. | S10: Not set | T10: 18% GST | U10: Not confirmed: CRM basis is empty; draft gives a GST rate, not whether prices include it | V10: Not given | W10: Active, not quotable (Rs 0) | X10: Category notes only (beds). No service-specific notes. | Y10: Y | Z10: Y | AB10: Unpriced, No B2B, GST basis, Knowledge | AC10: 0 | AD10: 1 | AE10: 1 | AF10: 1 | AG10: 0 | AH10: 1 | AI10: 0
A11: ADULT-DIAP | C11: Adult Diapers Tape-Style (Pack of 10 Large) | D11: consumables | E11: Book My Medicare (BMM) | F11: Book My Medicare (BMM) | H11: box | I11: Only one source; unit as given | K11: 550 | M11: Not on the CRM rate card | N11: Not loaded | O11: 360 | P11: =IF(AND(ISNUMBER(J11),J11>0),ROUND(J11*Assumptions!$B$4,2),"") | Q11: =IF(AND(ISNUMBER(K11),ISNUMBER(O11)),IF(ROUND(K11*Assumptions!$B$4,2)=O11,"Equals 70%","Differs ("&TEXT(O11/K11,"0%")&" of B2C)"),"") -> Differs (65% of B2C) | R11: Not loaded. Draft B2B is unapproved. | T11: 12% GST | U11: Not confirmed: CRM basis is empty; draft gives a GST rate, not whether prices include it | V11: Not given | W11: Not loaded | X11: No service yet. Category notes (consumables) would apply after import. | Y11: N | Z11: Y | AB11: GST basis, Knowledge | AC11: 0 | AD11: 1 | AE11: 0 | AF11: 1 | AG11: 0 | AH11: 0 | AI11: 0
A12: BIPAP-MASK | C12: Full-Face Non-Vented BiPAP Cushion Mask | D12: consumables | E12: Book My Medicare (BMM) | F12: Book My Medicare (BMM) | H12: unit | I12: Only one source; unit as given | K12: 2800 | M12: Not on the CRM rate card | N12: Not loaded | O12: 1800 | P12: =IF(AND(ISNUMBER(J12),J12>0),ROUND(J12*Assumptions!$B$4,2),"") | Q12: =IF(AND(ISNUMBER(K12),ISNUMBER(O12)),IF(ROUND(K12*Assumptions!$B$4,2)=O12,"Equals 70%","Differs ("&TEXT(O12/K12,"0%")&" of B2C)"),"") -> Differs (64% of B2C) | R12: Not loaded. Draft B2B is unapproved. | T12: 12% GST | U12: Not confirmed: CRM basis is empty; draft gives a GST rate, not whether prices include it | V12: Not given | W12: Not loaded | X12: No service yet. Category notes (consumables) would apply after import. | Y12: N | Z12: Y | AB12: GST basis, Knowledge | AC12: 0 | AD12: 1 | AE12: 0 | AF12: 1 | AG12: 0 | AH12: 0 | AI12: 0
A13: CAVILON-SP | B13: 3M Cavilon No-Sting Barrier Film Spray | C13: 3M Cavilon No-Sting Barrier Film Spray (28ml) | D13: consumables | E13: Book My Medicare (BMM) | F13: Book My Medicare (BMM) | G13: unit | H13: unit | I13: Same unit | J13: 0 | K13: 1100 | M13: Not priced: Rs 0 placeholder, agents see "quote required" | N13: None (0 buying rates in CRM) | O13: 750 | P13: =IF(AND(ISNUMBER(J13),J13>0),ROUND(J13*Assumptions!$B$4,2),"") | Q13: =IF(AND(ISNUMBER(K13),ISNUMBER(O13)),IF(ROUND(K13*Assumptions!$B$4,2)=O13,"Equals 70%","Differs ("&TEXT(O13/K13,"0%")&" of B2C)"),"") -> Differs (68% of B2C) | R13: No buying rate, and none derivable: no selling price. Draft B2B is unapproved. | S13: Not set | T13: 12% GST | U13: Not confirmed: CRM basis is empty; draft gives a GST rate, not whether prices include it | V13: Not given | W13: Active, not quotable (Rs 0) | X13: Category notes only (consumables). No service-specific notes. | Y13: Y | Z13: Y | AB13: Unpriced, No B2B, GST basis, Knowledge | AC13: 0 | AD13: 1 | AE13: 1 | AF13: 1 | AG13: 0 | AH13: 1 | AI13: 0
A14: FEED-SYR-60 | B14: Feeding Syringe (Catheter Tip 50/60ml) | C14: Catheter-Tip Feeding Syringes (60ml, Pack of 5) | D14: consumables | E14: Book My Medicare (BMM) | F14: Book My Medicare (BMM) | G14: unit | H14: box | I14: Pack size differs: rate card sells one syringe ("unit"), draft sells a pack of 5 ("box"). Different product; never convert. | J14: 0 | K14: 280 | M14: Not priced: Rs 0 placeholder, agents see "quote required" | N14: None (0 buying rates in CRM) | O14: 170 | P14: =IF(AND(ISNUMBER(J14),J14>0),ROUND(J14*Assumptions!$B$4,2),"") | Q14: =IF(AND(ISNUMBER(K14),ISNUMBER(O14)),IF(ROUND(K14*Assumptions!$B$4,2)=O14,"Equals 70%","Differs ("&TEXT(O14/K14,"0%")&" of B2C)"),"") -> Differs (61% of B2C) | R14: No buying rate, and none derivable: no selling price. Draft B2B is unapproved. | S14: Not set | T14: 12% GST | U14: Not confirmed: CRM basis is empty; draft gives a GST rate, not whether prices include it | V14: Not given | W14: Active, not quotable (Rs 0) | X14: Category notes only (consumables). No service-specific notes. | Y14: Y | Z14: Y | AB14: Unit, Unpriced, No B2B, GST basis, Knowledge | AC14: 1 | AD14: 1 | AE14: 1 | AF14: 1 | AG14: 0 | AH14: 1 | AI14: 0
A15: FOLEY-CATH | C15: Silicone Foley Balloon Catheter (All Sizes) | D15: consumables | E15: Book My Medicare (BMM) | F15: Book My Medicare (BMM) | H15: unit | I15: Only one source; unit as given | K15: 320 | M15: Not on the CRM rate card | N15: Not loaded | O15: 190 | P15: =IF(AND(ISNUMBER(J15),J15>0),ROUND(J15*Assumptions!$B$4,2),"") | Q15: =IF(AND(ISNUMBER(K15),ISNUMBER(O15)),IF(ROUND(K15*Assumptions!$B$4,2)=O15,"Equals 70%","Differs ("&TEXT(O15/K15,"0%")&" of B2C)"),"") -> Differs (59% of B2C) | R15: Not loaded. Draft B2B is unapproved. | T15: 12% GST | U15: Not confirmed: CRM basis is empty; draft gives a GST rate, not whether prices include it | V15: Not given | W15: Not loaded | X15: No service yet. Category notes (consumables) would apply after import. | Y15: N | Z15: Y | AB15: GST basis, Knowledge | AC15: 0 | AD15: 1 | AE15: 0 | AF15: 1 | AG15: 0 | AH15: 0 | AI15: 0
A16: GLOVES-BOX | B16: Examination Gloves Box (100 pcs) | C16: Examination Gloves Box (Powder-Free, 100 pcs) | D16: consumables | E16: Book My Medicare (BMM) | F16: Book My Medicare (BMM) | G16: box | H16: box | I16: Same unit | J16: 0 | K16: 450 | M16: Not priced: Rs 0 placeholder, agents see "quote required" | N16: None (0 buying rates in CRM) | O16: 280 | P16: =IF(AND(ISNUMBER(J16),J16>0),ROUND(J16*Assumptions!$B$4,2),"") | Q16: =IF(AND(ISNUMBER(K16),ISNUMBER(O16)),IF(ROUND(K16*Assumptions!$B$4,2)=O16,"Equals 70%","Differs ("&TEXT(O16/K16,"0%")&" of B2C)"),"") -> Differs (62% of B2C) | R16: No buying rate, and none derivable: no selling price. Draft B2B is unapproved. | S16: Not set | T16: 12% GST | U16: Not confirmed: CRM basis is empty; draft gives a GST rate, not whether prices include it | V16: Not given | W16: Active, not quotable (Rs 0) | X16: Category notes only (consumables). No service-specific notes. | Y16: Y | Z16: Y | AB16: Unpriced, No B2B, GST basis, Knowledge | AC16: 0 | AD16: 1 | AE16: 1 | AF16: 1 | AG16: 0 | AH16: 1 | AI16: 0
A17: GLOVES-STER | C17: Surgical Sterile Gloves Pairs (Pack of 10) | D17: consumables | E17: Book My Medicare (BMM) | F17: Book My Medicare (BMM) | H17: box | I17: Only one source; unit as given | K17: 350 | M17: Not on the CRM rate card | N17: Not loaded | O17: 220 | P17: =IF(AND(ISNUMBER(J17),J17>0),ROUND(J17*Assumptions!$B$4,2),"") | Q17: =IF(AND(ISNUMBER(K17),ISNUMBER(O17)),IF(ROUND(K17*Assumptions!$B$4,2)=O17,"Equals 70%","Differs ("&TEXT(O17/K17,"0%")&" of B2C)"),"") -> Differs (63% of B2C) | R17: Not loaded. Draft B2B is unapproved. | T17: 12% GST | U17: Not confirmed: CRM basis is empty; draft gives a GST rate, not whether prices include it | V17: Not given | W17: Not loaded | X17: No service yet. Category notes (consumables) would apply after import. | Y17: N | Z17: Y | AB17: GST basis, Knowledge | AC17: 0 | AD17: 1 | AE17: 0 | AF17: 1 | AG17: 0 | AH17: 0 | AI17: 0
A18: HFNC-KIT | C18: Optiflow Nasal Interface & Heated Breathing Tube | D18: consumables | E18: Book My Medicare (BMM) | F18: Book My Medicare (BMM) | H18: unit | I18: Only one source; unit as given | K18: 4500 | M18: Not on the CRM rate card | N18: Not loaded | O18: 3100 | P18: =IF(AND(ISNUMBER(J18),J18>0),ROUND(J18*Assumptions!$B$4,2),"") | Q18: =IF(AND(ISNUMBER(K18),ISNUMBER(O18)),IF(ROUND(K18*Assumptions!$B$4,2)=O18,"Equals 70%","Differs ("&TEXT(O18/K18,"0%")&" of B2C)"),"") -> Differs (69% of B2C) | R18: Not loaded. Draft B2B is unapproved. | T18: 12% GST | U18: Not confirmed: CRM basis is empty; draft gives a GST rate, not whether prices include it | V18: Not given | W18: Not loaded | X18: No service yet. Category notes (consumables) would apply after import. | Y18: N | Z18: Y | AB18: GST basis, Knowledge | AC18: 0 | AD18: 1 | AE18: 0 | AF18: 1 | AG18: 0 | AH18: 0 | AI18: 0
A19: HME-FILTER | C19: Heat & Moisture Exchanger (HME) Filter Pack | D19: consumables | E19: Book My Medicare (BMM) | F19: Book My Medicare (BMM) | H19: box | I19: Only one source; unit as given | K19: 650 | M19: Not on the CRM rate card | N19: Not loaded | O19: 400 | P19: =IF(AND(ISNUMBER(J19),J19>0),ROUND(J19*Assumptions!$B$4,2),"") | Q19: =IF(AND(ISNUMBER(K19),ISNUMBER(O19)),IF(ROUND(K19*Assumptions!$B$4,2)=O19,"Equals 70%","Differs ("&TEXT(O19/K19,"0%")&" of B2C)"),"") -> Differs (62% of B2C) | R19: Not loaded. Draft B2B is unapproved. | T19: 12% GST | U19: Not confirmed: CRM basis is empty; draft gives a GST rate, not whether prices include it | V19: Not given | W19: Not loaded | X19: No service yet. Category notes (consumables) would apply after import. | Y19: N | Z19: Y | AB19: GST basis, Knowledge | AC19: 0 | AD19: 1 | AE19: 0 | AF19: 1 | AG19: 0 | AH19: 0 | AI19: 0
A20: IV-CAN-SET | C20: IV Infusion Administration Set with Micro-Drip | D20: consumables | E20: Book My Medicare (BMM) | F20: Book My Medicare (BMM) | H20: unit | I20: Only one source; unit as given | K20: 140 | M20: Not on the CRM rate card | N20: Not loaded | O20: 75 | P20: =IF(AND(ISNUMBER(J20),J20>0),ROUND(J20*Assumptions!$B$4,2),"") | Q20: =IF(AND(ISNUMBER(K20),ISNUMBER(O20)),IF(ROUND(K20*Assumptions!$B$4,2)=O20,"Equals 70%","Differs ("&TEXT(O20/K20,"0%")&" of B2C)"),"") -> Differs (54% of B2C) | R20: Not loaded. Draft B2B is unapproved. | T20: 12% GST | U20: Not confirmed: CRM basis is empty; draft gives a GST rate, not whether prices include it | V20: Not given | W20: Not loaded | X20: No service yet. Category notes (consumables) would apply after import. | Y20: N | Z20: Y | AB20: GST basis, Knowledge | AC20: 0 | AD20: 1 | AE20: 0 | AF20: 1 | AG20: 0 | AH20: 0 | AI20: 0
A21: MOIST-CREAM | B21: Moisturex Soft Skin Barrier Cream | C21: Moisturex Soft Protective Barrier Emollient Cream | D21: consumables | E21: Book My Medicare (BMM) | F21: Book My Medicare (BMM) | G21: unit | H21: unit | I21: Same unit | J21: 0 | K21: 380 | M21: Not priced: Rs 0 placeholder, agents see "quote required" | N21: None (0 buying rates in CRM) | O21: 240 | P21: =IF(AND(ISNUMBER(J21),J21>0),ROUND(J21*Assumptions!$B$4,2),"") | Q21: =IF(AND(ISNUMBER(K21),ISNUMBER(O21)),IF(ROUND(K21*Assumptions!$B$4,2)=O21,"Equals 70%","Differs ("&TEXT(O21/K21,"0%")&" of B2C)"),"") -> Differs (63% of B2C) | R21: No buying rate, and none derivable: no selling price. Draft B2B is unapproved. | S21: Not set | T21: 12% GST | U21: Not confirmed: CRM basis is empty; draft gives a GST rate, not whether prices include it | V21: Not given | W21: Active, not quotable (Rs 0) | X21: Category notes only (consumables). No service-specific notes. | Y21: Y | Z21: Y | AB21: Unpriced, No B2B, GST basis, Knowledge | AC21: 0 | AD21: 1 | AE21: 1 | AF21: 1 | AG21: 0 | AH21: 1 | AI21: 0
A22: MOUTH-CHX | B22: Chlorhexidine Mouthwash (Oral Care) | C22: Chlorhexidine Gluconate 0.2% Oral Care Rinse | D22: consumables | E22: Book My Medicare (BMM) | F22: Book My Medicare (BMM) | G22: unit | H22: unit | I22: Same unit | J22: 0 | K22: 160 | M22: Not priced: Rs 0 placeholder, agents see "quote required" | N22: None (0 buying rates in CRM) | O22: 95 | P22: =IF(AND(ISNUMBER(J22),J22>0),ROUND(J22*Assumptions!$B$4,2),"") | Q22: =IF(AND(ISNUMBER(K22),ISNUMBER(O22)),IF(ROUND(K22*Assumptions!$B$4,2)=O22,"Equals 70%","Differs ("&TEXT(O22/K22,"0%")&" of B2C)"),"") -> Differs (59% of B2C) | R22: No buying rate, and none derivable: no selling price. Draft B2B is unapproved. | S22: Not set | T22: 12% GST | U22: Not confirmed: CRM basis is empty; draft gives a GST rate, not whether prices include it | V22: Not given | W22: Active, not quotable (Rs 0) | X22: Category notes only (consumables). No service-specific notes. | Y22: Y | Z22: Y | AB22: Unpriced, No B2B, GST basis, Knowledge | AC22: 0 | AD22: 1 | AE22: 1 | AF22: 1 | AG22: 0 | AH22: 1 | AI22: 0
A23: OXY-CANNULA | C23: Nasal Oxygen Cannula with Twin Prong Tubing | D23: consumables | E23: Book My Medicare (BMM) | F23: Book My Medicare (BMM) | H23: unit | I23: Only one source; unit as given | K23: 150 | M23: Not on the CRM rate card | N23: Not loaded | O23: 85 | P23: =IF(AND(ISNUMBER(J23),J23>0),ROUND(J23*Assumptions!$B$4,2),"") | Q23: =IF(AND(ISNUMBER(K23),ISNUMBER(O23)),IF(ROUND(K23*Assumptions!$B$4,2)=O23,"Equals 70%","Differs ("&TEXT(O23/K23,"0%")&" of B2C)"),"") -> Differs (57% of B2C) | R23: Not loaded. Draft B2B is unapproved. | T23: 12% GST | U23: Not confirmed: CRM basis is empty; draft gives a GST rate, not whether prices include it | V23: Not given | W23: Not loaded | X23: No service yet. Category notes (consumables) would apply after import. | Y23: N | Z23: Y | AB23: GST basis, Knowledge | AC23: 0 | AD23: 1 | AE23: 0 | AF23: 1 | AG23: 0 | AH23: 0 | AI23: 0
A24: OXY-MASK | C24: Venturi / High-Concentration Oxygen Mask | D24: consumables | E24: Book My Medicare (BMM) | F24: Book My Medicare (BMM) | H24: unit | I24: Only one source; unit as given | K24: 240 | M24: Not on the CRM rate card | N24: Not loaded | O24: 140 | P24: =IF(AND(ISNUMBER(J24),J24>0),ROUND(J24*Assumptions!$B$4,2),"") | Q24: =IF(AND(ISNUMBER(K24),ISNUMBER(O24)),IF(ROUND(K24*Assumptions!$B$4,2)=O24,"Equals 70%","Differs ("&TEXT(O24/K24,"0%")&" of B2C)"),"") -> Differs (58% of B2C) | R24: Not loaded. Draft B2B is unapproved. | T24: 12% GST | U24: Not confirmed: CRM basis is empty; draft gives a GST rate, not whether prices include it | V24: Not given | W24: Not loaded | X24: No service yet. Category notes (consumables) would apply after import. | Y24: N | Z24: Y | AB24: GST basis, Knowledge | AC24: 0 | AD24: 1 | AE24: 0 | AF24: 1 | AG24: 0 | AH24: 0 | AI24: 0
A25: RYLE-TUBE | C25: Ryle's Nasogastric Feeding Tube with Guide Wire | D25: consumables | E25: Book My Medicare (BMM) | F25: Book My Medicare (BMM) | H25: unit | I25: Only one source; unit as given | K25: 220 | M25: Not on the CRM rate card | N25: Not loaded | O25: 130 | P25: =IF(AND(ISNUMBER(J25),J25>0),ROUND(J25*Assumptions!$B$4,2),"") | Q25: =IF(AND(ISNUMBER(K25),ISNUMBER(O25)),IF(ROUND(K25*Assumptions!$B$4,2)=O25,"Equals 70%","Differs ("&TEXT(O25/K25,"0%")&" of B2C)"),"") -> Differs (59% of B2C) | R25: Not loaded. Draft B2B is unapproved. | T25: 12% GST | U25: Not confirmed: CRM basis is empty; draft gives a GST rate, not whether prices include it | V25: Not given | W25: Not loaded | X25: No service yet. Category notes (consumables) would apply after import. | Y25: N | Z25: Y | AB25: GST basis, Knowledge | AC25: 0 | AD25: 1 | AE25: 0 | AF25: 1 | AG25: 0 | AH25: 0 | AI25: 0
A26: SUCT-CATH | C26: Mucus Extractor & Suction Catheters (10 pcs) | D26: consumables | E26: Book My Medicare (BMM) | F26: Book My Medicare (BMM) | H26: box | I26: Only one source; unit as given | K26: 220 | M26: Not on the CRM rate card | N26: Not loaded | O26: 130 | P26: =IF(AND(ISNUMBER(J26),J26>0),ROUND(J26*Assumptions!$B$4,2),"") | Q26: =IF(AND(ISNUMBER(K26),ISNUMBER(O26)),IF(ROUND(K26*Assumptions!$B$4,2)=O26,"Equals 70%","Differs ("&TEXT(O26/K26,"0%")&" of B2C)"),"") -> Differs (59% of B2C) | R26: Not loaded. Draft B2B is unapproved. | T26: 12% GST | U26: Not confirmed: CRM basis is empty; draft gives a GST rate, not whether prices include it | V26: Not given | W26: Not loaded | X26: No service yet. Category notes (consumables) would apply after import. | Y26: N | Z26: Y | AB26: GST basis, Knowledge | AC26: 0 | AD26: 1 | AE26: 0 | AF26: 1 | AG26: 0 | AH26: 0 | AI26: 0
A27: TRACH-TUBE | C27: Cuffed / Uncuffed Tracheostomy Tube (Shiley Type) | D27: consumables | E27: Book My Medicare (BMM) | F27: Book My Medicare (BMM) | H27: unit | I27: Only one source; unit as given | K27: 1950 | M27: Not on the CRM rate card | N27: Not loaded | O27: 1300 | P27: =IF(AND(ISNUMBER(J27),J27>0),ROUND(J27*Assumptions!$B$4,2),"") | Q27: =IF(AND(ISNUMBER(K27),ISNUMBER(O27)),IF(ROUND(K27*Assumptions!$B$4,2)=O27,"Equals 70%","Differs ("&TEXT(O27/K27,"0%")&" of B2C)"),"") -> Differs (67% of B2C) | R27: Not loaded. Draft B2B is unapproved. | T27: 12% GST | U27: Not confirmed: CRM basis is empty; draft gives a GST rate, not whether prices include it | V27: Not given | W27: Not loaded | X27: No service yet. Category notes (consumables) would apply after import. | Y27: N | Z27: Y | AB27: GST basis, Knowledge | AC27: 0 | AD27: 1 | AE27: 0 | AF27: 1 | AG27: 0 | AH27: 0 | AI27: 0
A28: UNDER-PAD | C28: Super-Absorbent Bed Underpads (Pack of 10) | D28: consumables | E28: Book My Medicare (BMM) | F28: Book My Medicare (BMM) | H28: box | I28: Only one source; unit as given | K28: 420 | M28: Not on the CRM rate card | N28: Not loaded | O28: 260 | P28: =IF(AND(ISNUMBER(J28),J28>0),ROUND(J28*Assumptions!$B$4,2),"") | Q28: =IF(AND(ISNUMBER(K28),ISNUMBER(O28)),IF(ROUND(K28*Assumptions!$B$4,2)=O28,"Equals 70%","Differs ("&TEXT(O28/K28,"0%")&" of B2C)"),"") -> Differs (62% of B2C) | R28: Not loaded. Draft B2B is unapproved. | T28: 12% GST | U28: Not confirmed: CRM basis is empty; draft gives a GST rate, not whether prices include it | V28: Not given | W28: Not loaded | X28: No service yet. Category notes (consumables) would apply after import. | Y28: N | Z28: Y | AB28: GST basis, Knowledge | AC28: 0 | AD28: 1 | AE28: 0 | AF28: 1 | AG28: 0 | AH28: 0 | AI28: 0
A29: URO-BAG | C29: Urine Drainage Collection Bag with Anti-Reflux | D29: consumables | E29: Book My Medicare (BMM) | F29: Book My Medicare (BMM) | H29: unit | I29: Only one source; unit as given | K29: 180 | M29: Not on the CRM rate card | N29: Not loaded | O29: 95 | P29: =IF(AND(ISNUMBER(J29),J29>0),ROUND(J29*Assumptions!$B$4,2),"") | Q29: =IF(AND(ISNUMBER(K29),ISNUMBER(O29)),IF(ROUND(K29*Assumptions!$B$4,2)=O29,"Equals 70%","Differs ("&TEXT(O29/K29,"0%")&" of B2C)"),"") -> Differs (53% of B2C) | R29: Not loaded. Draft B2B is unapproved. | T29: 12% GST | U29: Not confirmed: CRM basis is empty; draft gives a GST rate, not whether prices include it | V29: Not given | W29: Not loaded | X29: No service yet. Category notes (consumables) would apply after import. | Y29: N | Z29: Y | AB29: GST basis, Knowledge | AC29: 0 | AD29: 1 | AE29: 0 | AF29: 1 | AG29: 0 | AH29: 0 | AI29: 0
A30: VENT-CIRCUIT | C30: Dual-Limb Ventilator Patient Circuit with Chamber | D30: consumables | E30: Book My Medicare (BMM) | F30: Book My Medicare (BMM) | H30: unit | I30: Only one source; unit as given | K30: 1800 | M30: Not on the CRM rate card | N30: Not loaded | O30: 1200 | P30: =IF(AND(ISNUMBER(J30),J30>0),ROUND(J30*Assumptions!$B$4,2),"") | Q30: =IF(AND(ISNUMBER(K30),ISNUMBER(O30)),IF(ROUND(K30*Assumptions!$B$4,2)=O30,"Equals 70%","Differs ("&TEXT(O30/K30,"0%")&" of B2C)"),"") -> Differs (67% of B2C) | R30: Not loaded. Draft B2B is unapproved. | T30: 12% GST | U30: Not confirmed: CRM basis is empty; draft gives a GST rate, not whether prices include it | V30: Not given | W30: Not loaded | X30: No service yet. Category notes (consumables) would apply after import. | Y30: N | Z30: Y | AB30: GST basis, Knowledge | AC30: 0 | AD30: 1 | AE30: 0 | AF30: 1 | AG30: 0 | AH30: 0 | AI30: 0
A31: ECG-12 | B31: ECG at home (12-lead) | C31: ECG at Home (12-Lead Diagnostic ECG) | D31: ecg | E31: SecondMedic (SM) | F31: SecondMedic (SM) | G31: unit | H31: test | I31: Rate card "unit" vs draft "test". The importer refuses the row until one wording is chosen. | J31: 900 | K31: 900 | M31: Price written by migration 20261008100500 (proposal deck). No in-app approval record or named approver in the repo. | N31: None (0 buying rates in CRM) | O31: 500 | P31: =IF(AND(ISNUMBER(J31),J31>0),ROUND(J31*Assumptions!$B$4,2),"") -> 630 | Q31: =IF(AND(ISNUMBER(K31),ISNUMBER(O31)),IF(ROUND(K31*Assumptions!$B$4,2)=O31,"Equals 70%","Differs ("&TEXT(O31/K31,"0%")&" of B2C)"),"") -> Differs (56% of B2C) | R31: No buying rate. The 70% rule can derive one at import from the selling price. Draft B2B is unapproved. | S31: Not set | T31: Exempt | U31: Not confirmed: CRM basis is empty; draft gives a GST rate, not whether prices include it | V31: Not given | W31: Active, quotable | X31: Category notes only (ecg). No service-specific notes. | Y31: Y | Z31: Y | AB31: Unit, No B2B, GST basis, Knowledge | AC31: 1 | AD31: 1 | AE31: 1 | AF31: 1 | AG31: 0 | AH31: 0 | AI31: 0
A32: ECG-RPT | C32: Follow-up / Repeat ECG at Home | D32: ecg | E32: SecondMedic (SM) | F32: SecondMedic (SM) | H32: test | I32: New item uses "test"; existing ecg services use "unit". Align the wording before import. | K32: 650 | M32: Not on the CRM rate card | N32: Not loaded | O32: 350 | P32: =IF(AND(ISNUMBER(J32),J32>0),ROUND(J32*Assumptions!$B$4,2),"") | Q32: =IF(AND(ISNUMBER(K32),ISNUMBER(O32)),IF(ROUND(K32*Assumptions!$B$4,2)=O32,"Equals 70%","Differs ("&TEXT(O32/K32,"0%")&" of B2C)"),"") -> Differs (54% of B2C) | R32: Not loaded. Draft B2B is unapproved. | T32: Exempt | U32: Not confirmed: CRM basis is empty; draft gives a GST rate, not whether prices include it | V32: Not given | W32: Not loaded | X32: No service yet. Category notes (ecg) would apply after import. | Y32: N | Z32: Y | AB32: Unit, GST basis, Knowledge | AC32: 1 | AD32: 1 | AE32: 0 | AF32: 1 | AG32: 0 | AH32: 0 | AI32: 0
A33: ATTEND-12H | B33: Attendant, 12-hour shift | C33: Trained Patient Attendant / Caretaker (12-Hour) | D33: eldercare | E33: Book My Medicare (BMM) | F33: Book My Medicare (BMM) | G33: shift | H33: shift | I33: 12-hour shift. Confirm "shift" means 12 hours for every provider. | J33: 0 | K33: 1200 | M33: Not priced: Rs 0 placeholder, agents see "quote required" | N33: None (0 buying rates in CRM) | O33: 900 | P33: =IF(AND(ISNUMBER(J33),J33>0),ROUND(J33*Assumptions!$B$4,2),"") | Q33: =IF(AND(ISNUMBER(K33),ISNUMBER(O33)),IF(ROUND(K33*Assumptions!$B$4,2)=O33,"Equals 70%","Differs ("&TEXT(O33/K33,"0%")&" of B2C)"),"") -> Differs (75% of B2C) | R33: No buying rate, and none derivable: no selling price. Draft B2B is unapproved. | S33: Not set | T33: Exempt | U33: Not confirmed: CRM basis is empty; draft gives a GST rate, not whether prices include it | V33: Not given | W33: Active, not quotable (Rs 0) | X33: Category notes only (eldercare). No service-specific notes. | Y33: Y | Z33: Y | AA33: ELDER-CARE | AB33: Unpriced, No B2B, GST basis, Knowledge, Possible overlap | AC33: 0 | AD33: 1 | AE33: 1 | AF33: 1 | AG33: 1 | AH33: 1 | AI33: 0
A34: ATTEND-24H | C34: Trained Patient Attendant / Caretaker (24-Hour) | D34: eldercare | E34: Book My Medicare (BMM) | F34: Book My Medicare (BMM) | H34: shift | I34: 24-hour cover labelled "shift", the same unit as the 12-hour services. Needs its own unit (e.g. "24 hours") before import. | K34: 2200 | M34: Not on the CRM rate card | N34: Not loaded | O34: 1650 | P34: =IF(AND(ISNUMBER(J34),J34>0),ROUND(J34*Assumptions!$B$4,2),"") | Q34: =IF(AND(ISNUMBER(K34),ISNUMBER(O34)),IF(ROUND(K34*Assumptions!$B$4,2)=O34,"Equals 70%","Differs ("&TEXT(O34/K34,"0%")&" of B2C)"),"") -> Differs (75% of B2C) | R34: Not loaded. Draft B2B is unapproved. | T34: Exempt | U34: Not confirmed: CRM basis is empty; draft gives a GST rate, not whether prices include it | V34: Not given | W34: Not loaded | X34: No service yet. Category notes (eldercare) would apply after import. | Y34: N | Z34: Y | AA34: ELDER-CARE | AB34: Unit, GST basis, Knowledge, Possible overlap | AC34: 1 | AD34: 1 | AE34: 0 | AF34: 1 | AG34: 1 | AH34: 0 | AI34: 0
A35: ELDER-CARE | B35: Elder care attendant | D35: eldercare | E35: Book My Medicare (BMM) | G35: unit | I35: Only one source; unit as given | J35: 0 | M35: Not priced: Rs 0 placeholder, agents see "quote required" | N35: None (0 buying rates in CRM) | P35: =IF(AND(ISNUMBER(J35),J35>0),ROUND(J35*Assumptions!$B$4,2),"") | Q35: =IF(AND(ISNUMBER(K35),ISNUMBER(O35)),IF(ROUND(K35*Assumptions!$B$4,2)=O35,"Equals 70%","Differs ("&TEXT(O35/K35,"0%")&" of B2C)"),"") | R35: No buying rate, and none derivable: no selling price. | S35: Not set | U35: Not confirmed: CRM basis is empty | V35: Not given | W35: Active, not quotable (Rs 0) | X35: Category notes only (eldercare). No service-specific notes. | Y35: Y | Z35: N | AA35: ATTEND-12H, ATTEND-24H | AB35: Unpriced, No B2B, GST basis, Knowledge, Possible overlap | AC35: 0 | AD35: 1 | AE35: 1 | AF35: 1 | AG35: 1 | AH35: 1 | AI35: 0
A36: AIRBED | B36: Air mattress, rental | C36: Alternating Pressure Bubble Air Mattress | D36: equipment | E36: Book My Medicare (BMM) | F36: Book My Medicare (BMM) | G36: day | H36: day | I36: Daily rental. No monthly rental rate exists in any source; a month is not 30 day rates. | J36: 0 | K36: 80 | M36: Not priced: Rs 0 placeholder, agents see "quote required" | N36: None (0 buying rates in CRM) | O36: 50 | P36: =IF(AND(ISNUMBER(J36),J36>0),ROUND(J36*Assumptions!$B$4,2),"") | Q36: =IF(AND(ISNUMBER(K36),ISNUMBER(O36)),IF(ROUND(K36*Assumptions!$B$4,2)=O36,"Equals 70%","Differs ("&TEXT(O36/K36,"0%")&" of B2C)"),"") -> Differs (63% of B2C) | R36: No buying rate, and none derivable: no selling price. Draft B2B is unapproved. | S36: Not set | T36: 18% GST | U36: Not confirmed: CRM basis is empty; draft gives a GST rate, not whether prices include it | V36: Not given | W36: Active, not quotable (Rs 0) | X36: Category notes only (equipment). No service-specific notes. | Y36: Y | Z36: Y | AB36: Unpriced, No B2B, GST basis, Knowledge | AC36: 0 | AD36: 1 | AE36: 1 | AF36: 1 | AG36: 0 | AH36: 1 | AI36: 0
A37: BIPAP-AUTO | C37: Auto BiPAP / CPAP Machine with Humidifier | D37: equipment | E37: Book My Medicare (BMM) | F37: Book My Medicare (BMM) | H37: day | I37: Daily rental. No monthly rental rate exists in any source; a month is not 30 day rates. | K37: 320 | M37: Not on the CRM rate card | N37: Not loaded | O37: 210 | P37: =IF(AND(ISNUMBER(J37),J37>0),ROUND(J37*Assumptions!$B$4,2),"") | Q37: =IF(AND(ISNUMBER(K37),ISNUMBER(O37)),IF(ROUND(K37*Assumptions!$B$4,2)=O37,"Equals 70%","Differs ("&TEXT(O37/K37,"0%")&" of B2C)"),"") -> Differs (66% of B2C) | R37: Not loaded. Draft B2B is unapproved. | T37: 12% GST | U37: Not confirmed: CRM basis is empty; draft gives a GST rate, not whether prices include it | V37: Not given | W37: Not loaded | X37: No service yet. Category notes (equipment) would apply after import. | Y37: N | Z37: Y | AA37: VENT-HOME | AB37: GST basis, Knowledge, Possible overlap | AC37: 0 | AD37: 1 | AE37: 0 | AF37: 1 | AG37: 1 | AH37: 0 | AI37: 0
A38: BP-MONITOR | B38: Blood Pressure Apparatus (Digital/Manual) | C38: Digital NIBP Blood Pressure Monitor | D38: equipment | E38: Book My Medicare (BMM) | F38: Book My Medicare (BMM) | G38: day | H38: day | I38: Daily rental. No monthly rental rate exists in any source; a month is not 30 day rates. | J38: 0 | K38: 50 | M38: Not priced: Rs 0 placeholder, agents see "quote required" | N38: None (0 buying rates in CRM) | O38: 30 | P38: =IF(AND(ISNUMBER(J38),J38>0),ROUND(J38*Assumptions!$B$4,2),"") | Q38: =IF(AND(ISNUMBER(K38),ISNUMBER(O38)),IF(ROUND(K38*Assumptions!$B$4,2)=O38,"Equals 70%","Differs ("&TEXT(O38/K38,"0%")&" of B2C)"),"") -> Differs (60% of B2C) | R38: No buying rate, and none derivable: no selling price. Draft B2B is unapproved. | S38: Not set | T38: 12% GST | U38: Not confirmed: CRM basis is empty; draft gives a GST rate, not whether prices include it | V38: Not given | W38: Active, not quotable (Rs 0) | X38: Category notes only (equipment). No service-specific notes. | Y38: Y | Z38: Y | AB38: Unpriced, No B2B, GST basis, Knowledge | AC38: 0 | AD38: 1 | AE38: 1 | AF38: 1 | AG38: 0 | AH38: 1 | AI38: 0
A39: GLUCOMETER | C39: Glucometer Device with Lancing Pen | D39: equipment | E39: Book My Medicare (BMM) | F39: Book My Medicare (BMM) | H39: unit | I39: Only one source; unit as given | K39: 950 | M39: Not on the CRM rate card | N39: Not loaded | O39: 620 | P39: =IF(AND(ISNUMBER(J39),J39>0),ROUND(J39*Assumptions!$B$4,2),"") | Q39: =IF(AND(ISNUMBER(K39),ISNUMBER(O39)),IF(ROUND(K39*Assumptions!$B$4,2)=O39,"Equals 70%","Differs ("&TEXT(O39/K39,"0%")&" of B2C)"),"") -> Differs (65% of B2C) | R39: Not loaded. Draft B2B is unapproved. | T39: 12% GST | U39: Not confirmed: CRM basis is empty; draft gives a GST rate, not whether prices include it | V39: Not given | W39: Not loaded | X39: No service yet. Category notes (equipment) would apply after import. | Y39: N | Z39: Y | AB39: GST basis, Knowledge | AC39: 0 | AD39: 1 | AE39: 0 | AF39: 1 | AG39: 0 | AH39: 0 | AI39: 0
A40: HFNC | B40: High-flow (HF) oxygen machine, rental | C40: High-Flow Nasal Cannula (Airvo 2) System | D40: equipment | E40: Book My Medicare (BMM) | F40: Book My Medicare (BMM) | G40: day | H40: day | I40: Daily rental. No monthly rental rate exists in any source; a month is not 30 day rates. | J40: 0 | K40: 1200 | M40: Not priced: Rs 0 placeholder, agents see "quote required" | N40: None (0 buying rates in CRM) | O40: 800 | P40: =IF(AND(ISNUMBER(J40),J40>0),ROUND(J40*Assumptions!$B$4,2),"") | Q40: =IF(AND(ISNUMBER(K40),ISNUMBER(O40)),IF(ROUND(K40*Assumptions!$B$4,2)=O40,"Equals 70%","Differs ("&TEXT(O40/K40,"0%")&" of B2C)"),"") -> Differs (67% of B2C) | R40: No buying rate, and none derivable: no selling price. Draft B2B is unapproved. | S40: Not set | T40: 12% GST | U40: Not confirmed: CRM basis is empty; draft gives a GST rate, not whether prices include it | V40: Not given | W40: Active, not quotable (Rs 0) | X40: Category notes only (equipment). No service-specific notes. | Y40: Y | Z40: Y | AB40: Unpriced, No B2B, GST basis, Knowledge | AC40: 0 | AD40: 1 | AE40: 1 | AF40: 1 | AG40: 0 | AH40: 1 | AI40: 0
A41: MONITOR | B41: Multipara monitor, rental | C41: Multipara Vital Signs Monitor (ECG, NIBP, SpO2, Temp) | D41: equipment | E41: Book My Medicare (BMM) | F41: Book My Medicare (BMM) | G41: day | H41: day | I41: Daily rental. No monthly rental rate exists in any source; a month is not 30 day rates. | J41: 0 | K41: 300 | M41: Not priced: Rs 0 placeholder, agents see "quote required" | N41: None (0 buying rates in CRM) | O41: 190 | P41: =IF(AND(ISNUMBER(J41),J41>0),ROUND(J41*Assumptions!$B$4,2),"") | Q41: =IF(AND(ISNUMBER(K41),ISNUMBER(O41)),IF(ROUND(K41*Assumptions!$B$4,2)=O41,"Equals 70%","Differs ("&TEXT(O41/K41,"0%")&" of B2C)"),"") -> Differs (63% of B2C) | R41: No buying rate, and none derivable: no selling price. Draft B2B is unapproved. | S41: Not set | T41: 12% GST | U41: Not confirmed: CRM basis is empty; draft gives a GST rate, not whether prices include it | V41: Not given | W41: Active, not quotable (Rs 0) | X41: Category notes only (equipment). No service-specific notes. | Y41: Y | Z41: Y | AB41: Unpriced, No B2B, GST basis, Knowledge | AC41: 0 | AD41: 1 | AE41: 1 | AF41: 1 | AG41: 0 | AH41: 1 | AI41: 0
A42: NEBULIZER | C42: Medical Compressor Nebulizer Machine | D42: equipment | E42: Book My Medicare (BMM) | F42: Book My Medicare (BMM) | H42: day | I42: Daily rental. No monthly rental rate exists in any source; a month is not 30 day rates. | K42: 60 | M42: Not on the CRM rate card | N42: Not loaded | O42: 35 | P42: =IF(AND(ISNUMBER(J42),J42>0),ROUND(J42*Assumptions!$B$4,2),"") | Q42: =IF(AND(ISNUMBER(K42),ISNUMBER(O42)),IF(ROUND(K42*Assumptions!$B$4,2)=O42,"Equals 70%","Differs ("&TEXT(O42/K42,"0%")&" of B2C)"),"") -> Differs (58% of B2C) | R42: Not loaded. Draft B2B is unapproved. | T42: 12% GST | U42: Not confirmed: CRM basis is empty; draft gives a GST rate, not whether prices include it | V42: Not given | W42: Not loaded | X42: No service yet. Category notes (equipment) would apply after import. | Y42: N | Z42: Y | AB42: GST basis, Knowledge | AC42: 0 | AD42: 1 | AE42: 0 | AF42: 1 | AG42: 0 | AH42: 0 | AI42: 0
...

Sheet Unresolved inputs
A1: Exact inputs still needed
A3: # | B3: Input | C3: Why it blocks | D3: Owner | E3: Where it is entered
A4: 1 | B4: The approved final service and price list (B2C), as a file | C4: Without it no row can be reconciled against an approved value, and nothing can be submitted. The only file in the repo is a planning draft generated by scripts/generate_excel_matrix.mjs with "baseline" prices. | D4: Hinduja management / SecondMedic ops | E4: Settings > Rate card > Import rates
A5: 2 | B5: Read access to the live CareDesk database (Supabase ref eilshdpbnhcohroujaui) or a supervisor export of Settings > Rate card | C5: The connected Supabase account cannot see this project ("You do not have permission"). Any imports or approvals made in the app since the migrations are not visible here. | D5: SecondMedic platform admin | E5: Supabase connector, or Rate card export
A6: 3 | B6: GST basis for the B2C column and for the B2B column (incl_gst / excl_gst / no_gst) | C6: The importer never assumes it; margins are withheld when bases differ or are unset. The draft gives rates (Exempt, 12%, 18%), not whether prices include GST. | D6: SecondMedic finance | E6: Import rates: GST basis selectors
A7: 4 | B7: Effective date for the import | C7: No source has one. Back-dated rates only warn; booked lines keep their snapshot cost. | D7: SecondMedic ops | E7: Import rates: effective date
A8: 5 | B8: Unit decisions (see Unit decisions sheet): 24 h vs shift, 12 hours vs shift, test vs unit, pack sizes, monthly rental | C8: The importer refuses unit mismatches and never converts. Open question already listed in docs/RATES-AND-MARGINS.md. | D8: SecondMedic ops with BMM | E8: Before the import file is built
A9: 6 | B9: Approved provider-specific buying rates, if any differ from 70% | C9: 94 of 95 draft B2B values are not 70% of B2C. Without approval they cannot be used; leaving B2B blank lets the 70% rule apply. | D9: SecondMedic commercial | E9: Rate card > Buying rates, or B2B column
A10: 7 | B10: Decision on generic vs specific codes (BED-HOSP, NURS-HOME, PHYSIO-HOME, ELDER-CARE, OXY-CONC, OXY-CYL, VENT-HOME vs BIPAP-AUTO, XR-HOME vs XR-CHEST / XR-LIMB) | C10: Keeping both gives agents two prices for one need. | D10: Hinduja management | E10: Rate card (deactivate) after decision
A11: 8 | B11: Approval evidence for the 15 prices already on the rate card | C11: They were written by migrations with an automatic approved_at and no approver. Confirm on the live Approvals page or by written Hinduja confirmation. | D11: Hinduja management | E11: Approvals history
A12: 9 | B12: Approved service-specific product notes (summary, questions, inclusions, exclusions, preparation, FAQs) | C12: None exist. Clinical content cannot be written from nothing. | D12: Hinduja clinical + BMM / SecondMedic service owners | E12: Product knowledge > Import
A13: 10 | B13: Named approver and date for scripts S-01 to S-09 and the 12 category notes | C13: Scripts were marked approved by migration (approved_by empty); the category notes migration says "Hinduja to review". | D13: Hinduja management / clinical | E13: Templates approval
A14: 11 | B14: Agent roster and the operations owner for training sign-off | C14: Needed to fill the attendance and competency record. | D14: SecondMedic ops | E14: Training workbook

Sheet Unit decisions
A1: Unit decisions needed before import
A2: Yellow cells are for the business owner. Nothing here is converted automatically.
A4: Code | B4: CRM unit | C4: Draft unit | D4: Question | E4: Decision | F4: Decided by | G4: Date
A5: FEED-SYR-60 | B5: unit | C5: box | D5: Pack size differs: rate card sells one syringe ("unit"), draft sells a pack of 5 ("box"). Different product; never convert.
A6: ECG-12 | B6: unit | C6: test | D6: Rate card "unit" vs draft "test". The importer refuses the row until one wording is chosen.
A7: ECG-RPT | C7: test | D7: New item uses "test"; existing ecg services use "unit". Align the wording before import.
A8: ATTEND-24H | C8: shift | D8: 24-hour cover labelled "shift", the same unit as the 12-hour services. Needs its own unit (e.g. "24 hours") before import.
A9: LAB-ABG | C9: test | D9: New item uses "test"; existing lab services use "unit". Align the wording before import.
A10: LAB-B12 | C10: test | D10: New item uses "test"; existing lab services use "unit". Align the wording before import.
A11: LAB-BLOODC | C11: test | D11: New item uses "test"; existing lab services use "unit". Align the wording before import.
A12: LAB-CBC | B12: unit | C12: test | D12: Rate card "unit" vs draft "test". The importer refuses the row until one wording is chosen.
A13: LAB-CRP | C13: test | D13: New item uses "test"; existing lab services use "unit". Align the wording before import.
A14: LAB-DDIMER | C14: test | D14: New item uses "test"; existing lab services use "unit". Align the wording before import.
A15: LAB-ELECT | C15: test | D15: New item uses "test"; existing lab services use "unit". Align the wording before import.
A16: LAB-HBA1C | B16: unit | C16: test | D16: Rate card "unit" vs draft "test". The importer refuses the row until one wording is chosen.
A17: LAB-ICUPAN | C17: test | D17: New item uses "test"; existing lab services use "unit". Align the wording before import.
A18: LAB-KFT | B18: unit | C18: test | D18: Rate card "unit" vs draft "test". The importer refuses the row until one wording is chosen.
A19: LAB-LFT | B19: unit | C19: test | D19: Rate card "unit" vs draft "test". The importer refuses the row until one wording is chosen.
A20: LAB-LIPID | B20: unit | C20: test | D20: Rate card "unit" vs draft "test". The importer refuses the row until one wording is chosen.
A21: LAB-PANEL | B21: unit | C21: test | D21: Rate card "unit" vs draft "test". The importer refuses the row until one wording is chosen.
A22: LAB-PROCAL | C22: test | D22: New item uses "test"; existing lab services use "unit". Align the wording before import.
A23: LAB-PTINR | C23: test | D23: New item uses "test"; existing lab services use "unit". Align the wording before import.
A24: LAB-THY | B24: unit | C24: test | D24: Rate card "unit" vs draft "test". The importer refuses the row until one wording is chosen.
A25: LAB-URINE | C25: test | D25: New item uses "test"; existing lab services use "unit". Align the wording before import.
A26: LAB-URINEC | C26: test | D26: New item uses "test"; existing lab services use "unit". Align the wording before import.
A27: LAB-VITD | C27: test | D27: New item uses "test"; existing lab services use "unit". Align the wording before import.
A28: NURSE-24H | C28: shift | D28: 24-hour cover labelled "shift", the same unit as the 12-hour services. Needs its own unit (e.g. "24 hours") before import.
A29: NURSE-ICU24 | C29: shift | D29: 24-hour cover labelled "shift", the same unit as the 12-hour services. Needs its own unit (e.g. "24 hours") before import.
A30: VISIT-STD | B30: unit | C30: visit | D30: Rate card "unit" vs draft "visit". The importer refuses the row until one wording is chosen.
A31: VISIT-URG | B31: unit | C31: visit | D31: Rate card "unit" vs draft "visit". The importer refuses the row until one wording is chosen.
A32: XR-ADDITIONAL | B32: 1 Additional X-ray Shoot | D32: Free-text unit "1 Additional X-ray Shoot". Confirm the intended unit wording; buying rates are stored against this exact text.
A33: XR-CHEST | B33: unit | C33: test | D33: Rate card "unit" vs draft "test". The importer refuses the row until one wording is chosen.
A34: XR-HOME | B34: First Shot | D34: Free-text unit "First Shot". Confirm the intended unit wording; buying rates are stored against this exact text.
A35: XR-LIMB | B35: unit | C35: test | D35: Rate card "unit" vs draft "test". The importer refuses the row until one wording is chosen.
A36: XR-PELV | C36: test | D36: New item uses "test"; existing xray services use "unit". Align the wording before import.
A37: XR-PRINT | B37: additional X-ray Print | D37: Free-text unit "additional X-ray Print". Confirm the intended unit wording; buying rates are stored against this exact text.
A38: XR-SPINE | C38: test | D38: New item uses "test"; existing xray services use "unit". Align the wording before import.
A39: ALL RENTALS | B39: day | C39: day | D39: Is a monthly rental tariff needed for beds and equipment? If yes, it is a separate unit ("month") with its own approved price, never 30 x the day rate.
A40: NURSING / ATTENDANT | B40: shift | C40: shift | D40: Do "12 hours" and "24 hours" replace or sit beside the existing shift services (open question in docs/RATES-AND-MARGINS.md)?

Sheet Draft values to confirm
A1: Draft values for business confirmation (not approved, not for import as they stand)
A2: Source: docs/HHCS_CRM_Feature_Matrix_and_Catalogue.xlsx, sheet "85 Services Catalogue", generated by scripts/generate_excel_matrix.mjs (commit 8f6b2b1). Use this only if the business confirms it is the price list; otherwise replace with the approved file.
A5: Code | B5: Name | C5: Category | D5: Unit | E5: Draft B2C (Rs) | F5: Draft B2B (Rs) | G5: Draft GST | H5: On CRM | I5: Confirmed B2C (Rs) | J5: Keep draft B2B or use 70%? | K5: Approver | L5: Date
A6: BED-FOWL | B6: Full Fowler 2-Function Hospital Bed (Rental) | C6: beds | D6: day | E6: 240 | F6: 160 | G6: 18% GST | H6: N
A7: BED-ICU | B7: Motorized ICU Bed (3/5 Function with Remote) | C7: beds | D7: day | E7: 450 | F7: 300 | G7: 18% GST | H7: Y
A8: BED-SEMI | B8: Semi-Fowler Hospital Bed with Railings (Rental) | C8: beds | D8: day | E8: 180 | F8: 120 | G8: 18% GST | H8: N
A9: TYNA-BED | B9: Tubular High-Risk Pressure Redistribution Bed | C9: beds | D9: day | E9: 150 | F9: 100 | G9: 18% GST | H9: Y
A10: ADULT-DIAP | B10: Adult Diapers Tape-Style (Pack of 10 Large) | C10: consumables | D10: box | E10: 550 | F10: 360 | G10: 12% GST | H10: N
A11: BIPAP-MASK | B11: Full-Face Non-Vented BiPAP Cushion Mask | C11: consumables | D11: unit | E11: 2800 | F11: 1800 | G11: 12% GST | H11: N
A12: CAVILON-SP | B12: 3M Cavilon No-Sting Barrier Film Spray (28ml) | C12: consumables | D12: unit | E12: 1100 | F12: 750 | G12: 12% GST | H12: Y
A13: FEED-SYR-60 | B13: Catheter-Tip Feeding Syringes (60ml, Pack of 5) | C13: consumables | D13: box | E13: 280 | F13: 170 | G13: 12% GST | H13: Y
A14: FOLEY-CATH | B14: Silicone Foley Balloon Catheter (All Sizes) | C14: consumables | D14: unit | E14: 320 | F14: 190 | G14: 12% GST | H14: N
A15: GLOVES-BOX | B15: Examination Gloves Box (Powder-Free, 100 pcs) | C15: consumables | D15: box | E15: 450 | F15: 280 | G15: 12% GST | H15: Y
A16: GLOVES-STER | B16: Surgical Sterile Gloves Pairs (Pack of 10) | C16: consumables | D16: box | E16: 350 | F16: 220 | G16: 12% GST | H16: N
A17: HFNC-KIT | B17: Optiflow Nasal Interface & Heated Breathing Tube | C17: consumables | D17: unit | E17: 4500 | F17: 3100 | G17: 12% GST | H17: N
... A100: XR-SPINE | B100: Portable X-Ray: Spine (Cervical / Lumbar) | C100: xray | D100: test | E100: 2600 | F100: 1600 | G100: Exempt | H100: N

Sheet Knowledge coverage
A1: Product knowledge coverage
A3: Target | B3: Summary | C3: Who needs it | D3: Ask the caller | E3: Includes | F3: Excludes | G3: Preparation | H3: FAQ | I3: Status
A4: Category: beds | B4: Yes | C4: Yes | D4: Yes | E4: Yes | F4: Yes | G4: Yes | H4: Yes | I4: Seeded by migration 20261016110000 with the note "no clinical advice; Hinduja to review". Awaiting Hinduja review.
A5: Category: consumables | B5: Yes | C5: Yes | D5: Yes | E5: Yes | F5: Yes | G5: Yes | H5: Yes | I5: Seeded by migration 20261016110000 with the note "no clinical advice; Hinduja to review". Awaiting Hinduja review.
A6: Category: ecg | B6: Yes | C6: Yes | D6: Yes | E6: Yes | F6: Yes | G6: Yes | H6: Yes | I6: Seeded by migration 20261016110000 with the note "no clinical advice; Hinduja to review". Awaiting Hinduja review.
A7: Category: eldercare | B7: Yes | C7: Yes | D7: Yes | E7: Yes | F7: Yes | G7: Yes | H7: Yes | I7: Seeded by migration 20261016110000 with the note "no clinical advice; Hinduja to review". Awaiting Hinduja review.
A8: Category: equipment | B8: Yes | C8: Yes | D8: Yes | E8: Yes | F8: Yes | G8: Yes | H8: Yes | I8: Seeded by migration 20261016110000 with the note "no clinical advice; Hinduja to review". Awaiting Hinduja review.
A9: Category: homecare | B9: Yes | C9: Yes | D9: Yes | E9: Yes | F9: Yes | G9: Yes | H9: Yes | I9: Seeded by migration 20261016110000 with the note "no clinical advice; Hinduja to review". Awaiting Hinduja review.
A10: Category: icu | B10: Yes | C10: Yes | D10: Yes | E10: Yes | F10: Yes | G10: Yes | H10: Yes | I10: Seeded by migration 20261016110000 with the note "no clinical advice; Hinduja to review". Awaiting Hinduja review.
A11: Category: lab | B11: Yes | C11: Yes | D11: Yes | E11: Yes | F11: Yes | G11: Yes | H11: Yes | I11: Seeded by migration 20261016110000 with the note "no clinical advice; Hinduja to review". Awaiting Hinduja review.
A12: Category: nursing | B12: Yes | C12: Yes | D12: Yes | E12: Yes | F12: Yes | G12: Yes | H12: Yes | I12: Seeded by migration 20261016110000 with the note "no clinical advice; Hinduja to review". Awaiting Hinduja review.
A13: Category: physio | B13: Yes | C13: Yes | D13: Yes | E13: Yes | F13: Yes | G13: Yes | H13: Yes | I13: Seeded by migration 20261016110000 with the note "no clinical advice; Hinduja to review". Awaiting Hinduja review.
A14: Category: visit | B14: Yes | C14: Yes | D14: Yes | E14: Yes | F14: Yes | G14: Yes | H14: Yes | I14: Seeded by migration 20261016110000 with the note "no clinical advice; Hinduja to review". Awaiting Hinduja review.
... A18: Category "other" | B18: No | C18: No | D18: No | E18: No | F18: No | G18: No | H18: No | I18: No default; no service uses it today, but the 70% import routes "other" (e.g. ambulance) to BMM, so a new service there would show "No product knowledge yet".

Sheet Scripts review
A1: Call scripts reviewed against dispositions and the rate card
A3: Code | B3: Title | C3: Stage | D3: Ends with | E3: Finding | F3: Proposed change | G3: Needs approval from
A4: S-01 | B4: Inbound greeting & consent | C4: Opening | D4: Intake disposition | E4: Consent step and S-09 hand-off are sound. Step 7 promises a quote on WhatsApp "shortly", but 25 BMM services are not priced and are quoted after assessment. | F4: Step 7: "You will receive the quote on WhatsApp. For nursing, equipment and beds the quote follows the home assessment." | G4: Hinduja management
A5: S-02 | B5: Home Assessment & Pricing Explanation | C5: Opening / pricing | D5: Assessment booked | E5: Hard-codes "Hinduja Home Care" where S-01 uses {{brand}}. States the nurse is "Hinduja-certified": a claim to confirm. | F5: Use {{brand}}; confirm or remove "Hinduja-certified". | G5: Hinduja management
A6: S-03 | B6: Callback opening (missed call) | C6: Opening / follow-up | D6: Callback outcome | E6: Step 3 says close as "Not reached". That outcome does not exist: outcomes are Resolved, Follow-up needed, Wrong number, No longer needed, and a connected call is never unreachable (migration 20261015180000). | F6: Step 3: "If wrong person: apologise, confirm the number and close the callback with the outcome Wrong number." | G6: Hinduja management
A7: S-04 | B7: Discharge home-care requirement capture | C7: Requirement capture | D7: Intake disposition (step 8) | E7: Matches the intake form and the 8 dispositions. Mentions 24 h needs, but no 24 h service is on the rate card. | F7: None until the unit decision on 24 h is made. | G7: n/a
A8: S-05 | B8: Diagnostics at home (tests, X-ray, ECG) | C8: Requirement capture / pricing | D8: Intake disposition | E8: Tells agents to read the price from the Product knowledge panel. XR-HOME (Rs 2,000 first shot) and XR-CHEST (Rs 2,200) both fit "chest X-ray at home": two prices. | F8: After the overlap decision, name the code to quote for each X-ray request. | G8: Hinduja management
